Workbook

Sheet README
B2: Anvik Trail Co. — Sales Performance Dashboard
B3: Interactive Excel dashboard built entirely with formulas — no Power Query, no macros, no add-ins.
B5: What's here
B6: Raw Data — the messy source export (785 usable order rows), left completely untouched, plus
B7: formula-driven cleaning columns (J:Q) that trim whitespace, standardize casing, parse dates from
B8: 3 different formats, strip "$" from prices, and flag duplicate or invalid rows.
B9: Dashboard — filter cells (Region / Category / Channel / Date range) drive every KPI card, summary
B10: table, and chart on the sheet through SUMIFS formulas keyed off the cleaning flags.
B11: Data Cleaning Log — a formula-based tally of exactly what was wrong with the raw export and how
B12: many rows each issue affected.
B14: How to use it
B15: Change any yellow cell on the Dashboard sheet (Region, Category, Channel, or date range) and every
... B30: Light red row highlight on Raw Data = a row flagged invalid or duplicate by the cleaning logic

Sheet Raw Data
A1: OrderID | B1: OrderDate (raw) | C1: Region (raw) | D1: Category (raw) | E1: Product | F1: Quantity (raw) | G1: UnitPrice (raw) | H1: Channel | I1: Customer | J1: Clean Date | K1: Clean Region | L1: Clean Category | M1: Clean Qty | N1: Clean Price | O1: Is Duplicate? | P1: Is Valid? | Q1: Revenue
A2: 10159 | B2: 5-Apr-2025 | C2: SOUTH | D2: ACCESSORIES | E2: Trekking Poles | F2: 1 | G2: $49.35 | H2: Online | I2: Ava King | J2: =IFERROR(DATEVALUE(B2),"") -> 45752 | K2: =IF(A2="","",PROPER(TRIM(C2))) -> South | L2: =IF(A2="","",PROPER(TRIM(D2))) -> Accessories | M2: =IFERROR(VALUE(F2),0) -> 1 | N2: =IFERROR(VALUE(SUBSTITUTE(G2,"$","")),0) -> 49.35 | O2: =IF(A2="",0,IF(COUNTIF($A$2:A2,A2)>1,1,0)) -> 0 | P2: =IF(AND(A2<>"",J2<>"",M2>0,N2>0,O2=0),1,0) -> 1 | Q2: =IF(P2=1,M2*N2,0) -> 49.35
A3: 10365 | B3: 2025-01-13 | C3: Midwest | D3: ACCESSORIES | E3: Hydration Pack | F3: 1 | G3: 84.12 | H3: Wholesale | I3: Noah Rossi | J3: =IFERROR(DATEVALUE(B3),"") -> 45670 | K3: =IF(A3="","",PROPER(TRIM(C3))) -> Midwest | L3: =IF(A3="","",PROPER(TRIM(D3))) -> Accessories | M3: =IFERROR(VALUE(F3),0) -> 1 | N3: =IFERROR(VALUE(SUBSTITUTE(G3,"$","")),0) -> 84.12 | O3: =IF(A3="",0,IF(COUNTIF($A$2:A3,A3)>1,1,0)) -> 0 | P3: =IF(AND(A3<>"",J3<>"",M3>0,N3>0,O3=0),1,0) -> 1 | Q3: =IF(P3=1,M3*N3,0) -> 84.12
A4: 10039 | B4: 3-Aug-2024 | C4: WEST | D4: Climbing Gear | E4: Carabiner 5-Pack | F4: 1 | G4: 39.86 | H4: Wholesale | I4: Mia Lee | J4: =IFERROR(DATEVALUE(B4),"") -> 45507 | K4: =IF(A4="","",PROPER(TRIM(C4))) -> West | L4: =IF(A4="","",PROPER(TRIM(D4))) -> Climbing Gear | M4: =IFERROR(VALUE(F4),0) -> 1 | N4: =IFERROR(VALUE(SUBSTITUTE(G4,"$","")),0) -> 39.86 | O4: =IF(A4="",0,IF(COUNTIF($A$2:A4,A4)>1,1,0)) -> 0 | P4: =IF(AND(A4<>"",J4<>"",M4>0,N4>0,O4=0),1,0) -> 1 | Q4: =IF(P4=1,M4*N4,0) -> 39.86
A5: 10222 | B5: 2024-07-01 | C5: Midwest | D5: Footwear | E5: AlpineGrip Sandal | F5: 2 | G5: $50.28 | H5: Wholesale | I5: Olivia Lee | J5: =IFERROR(DATEVALUE(B5),"") -> 45474 | K5: =IF(A5="","",PROPER(TRIM(C5))) -> Midwest | L5: =IF(A5="","",PROPER(TRIM(D5))) -> Footwear | M5: =IFERROR(VALUE(F5),0) -> 2 | N5: =IFERROR(VALUE(SUBSTITUTE(G5,"$","")),0) -> 50.28 | O5: =IF(A5="",0,IF(COUNTIF($A$2:A5,A5)>1,1,0)) -> 0 | P5: =IF(AND(A5<>"",J5<>"",M5>0,N5>0,O5=0),1,0) -> 1 | Q5: =IF(P5=1,M5*N5,0) -> 100.56
A6: 10292 | B6: 2024-06-29 | C6: East | D6: CAMPING GEAR | E6: Camp Stove | F6: 3 | G6: $67.30 | H6: In-Store | I6: Grace Nguyen | J6: =IFERROR(DATEVALUE(B6),"") -> 45472 | K6: =IF(A6="","",PROPER(TRIM(C6))) -> East | L6: =IF(A6="","",PROPER(TRIM(D6))) -> Camping Gear | M6: =IFERROR(VALUE(F6),0) -> 3 | N6: =IFERROR(VALUE(SUBSTITUTE(G6,"$","")),0) -> 67.3 | O6: =IF(A6="",0,IF(COUNTIF($A$2:A6,A6)>1,1,0)) -> 0 | P6: =IF(AND(A6<>"",J6<>"",M6>0,N6>0,O6=0),1,0) -> 1 | Q6: =IF(P6=1,M6*N6,0) -> 201.9
A7: 10567 | B7: 2024-03-05 | C7: Midwest | D7: Footwear | E7: Trailblazer Hiking Boot | F7: 1 | G7: 119.86 | H7: In-Store | I7: Mia Lee | J7: =IFERROR(DATEVALUE(B7),"") -> 45356 | K7: =IF(A7="","",PROPER(TRIM(C7))) -> Midwest | L7: =IF(A7="","",PROPER(TRIM(D7))) -> Footwear | M7: =IFERROR(VALUE(F7),0) -> 1 | N7: =IFERROR(VALUE(SUBSTITUTE(G7,"$","")),0) -> 119.86 | O7: =IF(A7="",0,IF(COUNTIF($A$2:A7,A7)>1,1,0)) -> 0 | P7: =IF(AND(A7<>"",J7<>"",M7>0,N7>0,O7=0),1,0) -> 1 | Q7: =IF(P7=1,M7*N7,0) -> 119.86
A8: 10165 | B8: 2024-10-03 | C8: south | D8: FOOTWEAR | E8: Trailblazer Hiking Boot | F8: 2 | G8: $134.62 | H8: Online | I8: Layla Rossi | J8: =IFERROR(DATEVALUE(B8),"") -> 45568 | K8: =IF(A8="","",PROPER(TRIM(C8))) -> South | L8: =IF(A8="","",PROPER(TRIM(D8))) -> Footwear | M8: =IFERROR(VALUE(F8),0) -> 2 | N8: =IFERROR(VALUE(SUBSTITUTE(G8,"$","")),0) -> 134.62 | O8: =IF(A8="",0,IF(COUNTIF($A$2:A8,A8)>1,1,0)) -> 0 | P8: =IF(AND(A8<>"",J8<>"",M8>0,N8>0,O8=0),1,0) -> 1 | Q8: =IF(P8=1,M8*N8,0) -> 269.24
A9: 10501 | B9: 2024-10-29 | C9: Midwest | D9: FOOTWEAR | E9: AlpineGrip Sandal | F9: 1 | G9: $55.22 | H9: Online | I9: Layla Smith | J9: =IFERROR(DATEVALUE(B9),"") -> 45594 | K9: =IF(A9="","",PROPER(TRIM(C9))) -> Midwest | L9: =IF(A9="","",PROPER(TRIM(D9))) -> Footwear | M9: =IFERROR(VALUE(F9),0) -> 1 | N9: =IFERROR(VALUE(SUBSTITUTE(G9,"$","")),0) -> 55.22 | O9: =IF(A9="",0,IF(COUNTIF($A$2:A9,A9)>1,1,0)) -> 0 | P9: =IF(AND(A9<>"",J9<>"",M9>0,N9>0,O9=0),1,0) -> 1 | Q9: =IF(P9=1,M9*N9,0) -> 55.22
A10: 10310 | B10: 4-Nov-2024 | C10: Midwest | D10: APPAREL | E10: Merino Base Layer | F10: 3 | G10: 59.53 | H10: Online | I10: Owen Walker | J10: =IFERROR(DATEVALUE(B10),"") -> 45600 | K10: =IF(A10="","",PROPER(TRIM(C10))) -> Midwest | L10: =IF(A10="","",PROPER(TRIM(D10))) -> Apparel | M10: =IFERROR(VALUE(F10),0) -> 3 | N10: =IFERROR(VALUE(SUBSTITUTE(G10,"$","")),0) -> 59.53 | O10: =IF(A10="",0,IF(COUNTIF($A$2:A10,A10)>1,1,0)) -> 0 | P10: =IF(AND(A10<>"",J10<>"",M10>0,N10>0,O10=0),1,0) -> 1 | Q10: =IF(P10=1,M10*N10,0) -> 178.59
A11: 10429 | B11: 1/13/2024 | C11: West | D11: Climbing Gear | E11: Dynamic Rope 60m | F11: 3 | G11: $152.85 | H11: Online | I11: Lucas Hall | J11: =IFERROR(DATEVALUE(B11),"") -> 45304 | K11: =IF(A11="","",PROPER(TRIM(C11))) -> West | L11: =IF(A11="","",PROPER(TRIM(D11))) -> Climbing Gear | M11: =IFERROR(VALUE(F11),0) -> 3 | N11: =IFERROR(VALUE(SUBSTITUTE(G11,"$","")),0) -> 152.85 | O11: =IF(A11="",0,IF(COUNTIF($A$2:A11,A11)>1,1,0)) -> 0 | P11: =IF(AND(A11<>"",J11<>"",M11>0,N11>0,O11=0),1,0) -> 1 | Q11: =IF(P11=1,M11*N11,0) -> 458.55
A12: 10647 | B12: 29-Dec-2024 | C12: WEST | D12: Footwear | E12: AlpineGrip Sandal | F12: 0 | G12: 56.73 | H12: Online | I12: Ethan Walker | J12: =IFERROR(DATEVALUE(B12),"") -> 45655 | K12: =IF(A12="","",PROPER(TRIM(C12))) -> West | L12: =IF(A12="","",PROPER(TRIM(D12))) -> Footwear | M12: =IFERROR(VALUE(F12),0) -> 0 | N12: =IFERROR(VALUE(SUBSTITUTE(G12,"$","")),0) -> 56.73 | O12: =IF(A12="",0,IF(COUNTIF($A$2:A12,A12)>1,1,0)) -> 0 | P12: =IF(AND(A12<>"",J12<>"",M12>0,N12>0,O12=0),1,0) -> 0 | Q12: =IF(P12=1,M12*N12,0) -> 0
A13: 10514 | B13: 8/14/2024 | C13: West | D13: Accessories | E13: Hydration Pack | F13: 1 | G13: 84.90 | H13: Wholesale | I13: Maria Young | J13: =IFERROR(DATEVALUE(B13),"") -> 45518 | K13: =IF(A13="","",PROPER(TRIM(C13))) -> West | L13: =IF(A13="","",PROPER(TRIM(D13))) -> Accessories | M13: =IFERROR(VALUE(F13),0) -> 1 | N13: =IFERROR(VALUE(SUBSTITUTE(G13,"$","")),0) -> 84.9 | O13: =IF(A13="",0,IF(COUNTIF($A$2:A13,A13)>1,1,0)) -> 0 | P13: =IF(AND(A13<>"",J13<>"",M13>0,N13>0,O13=0),1,0) -> 1 | Q13: =IF(P13=1,M13*N13,0) -> 84.9
... A35: 10576 | B35: 2024-01-14 | C35: East | D35: ACCESSORIES | E35: Hydration Pack | F35: 2 | G35: 77.17 | H35: In-Store | I35: Mia Rossi | J35: =IFERROR(DATEVALUE(B35),"") -> 45305 | K35: =IF(A35="","",PROPER(TRIM(C35))) -> East | L35: =IF(A35="","",PROPER(TRIM(D35))) -> Accessories | M35: =IFERROR(VALUE(F35),0) -> 2 | N35: =IFERROR(VALUE(SUBSTITUTE(G35,"$","")),0) -> 77.17 | O35: =IF(A35="",0,IF(COUNTIF($A$2:A35,A35)>1,1,0)) -> 0 | P35: =IF(AND(A35<>"",J35<>"",M35>0,N35>0,O35=0),1,0) -> 1 | Q35: =IF(P35=1,M35*N35,0) -> 154.34
A36: 10188 | B36: 29-Dec-2024 | C36: EAST | D36: Accessories | E36: Trekking Poles | F36: 3 | H36: In-Store | I36: Olivia Garcia | J36: =IFERROR(DATEVALUE(B36),"") -> 45655 | K36: =IF(A36="","",PROPER(TRIM(C36))) -> East | L36: =IF(A36="","",PROPER(TRIM(D36))) -> Accessories | M36: =IFERROR(VALUE(F36),0) -> 3 | N36: =IFERROR(VALUE(SUBSTITUTE(G36,"$","")),0) -> 0 | O36: =IF(A36="",0,IF(COUNTIF($A$2:A36,A36)>1,1,0)) -> 0 | P36: =IF(AND(A36<>"",J36<>"",M36>0,N36>0,O36=0),1,0) -> 0 | Q36: =IF(P36=1,M36*N36,0) -> 0
A37: 10537 | B37: 2025-05-09 | C37: West | D37: CLIMBING GEAR | E37: Climbing Harness | F37: 3 | G37: $103.83 | H37: Online | I37: Lucas Brown | J37: =IFERROR(DATEVALUE(B37),"") -> 45786 | K37: =IF(A37="","",PROPER(TRIM(C37))) -> West | L37: =IF(A37="","",PROPER(TRIM(D37))) -> Climbing Gear | M37: =IFERROR(VALUE(F37),0) -> 3 | N37: =IFERROR(VALUE(SUBSTITUTE(G37,"$","")),0) -> 103.83 | O37: =IF(A37="",0,IF(COUNTIF($A$2:A37,A37)>1,1,0)) -> 0 | P37: =IF(AND(A37<>"",J37<>"",M37>0,N37>0,O37=0),1,0) -> 1 | Q37: =IF(P37=1,M37*N37,0) -> 311.49
A38: 10553 | B38: 2025-03-14 | C38: south | D38: camping gear | E38: 2-Person Tent | F38: 1 | G38: 252.95 | H38: Wholesale | I38: Layla Brown | J38: =IFERROR(DATEVALUE(B38),"") -> 45730 | K38: =IF(A38="","",PROPER(TRIM(C38))) -> South | L38: =IF(A38="","",PROPER(TRIM(D38))) -> Camping Gear | M38: =IFERROR(VALUE(F38),0) -> 1 | N38: =IFERROR(VALUE(SUBSTITUTE(G38,"$","")),0) -> 252.95 | O38: =IF(A38="",0,IF(COUNTIF($A$2:A38,A38)>1,1,0)) -> 0 | P38: =IF(AND(A38<>"",J38<>"",M38>0,N38>0,O38=0),1,0) -> 1 | Q38: =IF(P38=1,M38*N38,0) -> 252.95
A39: 10405 | B39: TBD | C39: West | D39: Climbing Gear | E39: Chalk Bag | F39: 4 | G39: 19.11 | H39: Wholesale | I39: Mia Walker | J39: =IFERROR(DATEVALUE(B39),"") | K39: =IF(A39="","",PROPER(TRIM(C39))) -> West | L39: =IF(A39="","",PROPER(TRIM(D39))) -> Climbing Gear | M39: =IFERROR(VALUE(F39),0) -> 4 | N39: =IFERROR(VALUE(SUBSTITUTE(G39,"$","")),0) -> 19.11 | O39: =IF(A39="",0,IF(COUNTIF($A$2:A39,A39)>1,1,0)) -> 0 | P39: =IF(AND(A39<>"",J39<>"",M39>0,N39>0,O39=0),1,0) -> 0 | Q39: =IF(P39=1,M39*N39,0) -> 0
A40: 10078 | B40: 2/4/2024 | C40: East | D40: ACCESSORIES | E40: Headlamp | F40: 1 | G40: $37.90 | H40: Online | I40: Lucas Rodriguez | J40: =IFERROR(DATEVALUE(B40),"") -> 45326 | K40: =IF(A40="","",PROPER(TRIM(C40))) -> East | L40: =IF(A40="","",PROPER(TRIM(D40))) -> Accessories | M40: =IFERROR(VALUE(F40),0) -> 1 | N40: =IFERROR(VALUE(SUBSTITUTE(G40,"$","")),0) -> 37.9 | O40: =IF(A40="",0,IF(COUNTIF($A$2:A40,A40)>1,1,0)) -> 0 | P40: =IF(AND(A40<>"",J40<>"",M40>0,N40>0,O40=0),1,0) -> 1 | Q40: =IF(P40=1,M40*N40,0) -> 37.9
A41: 10096 | B41: 2/1/2025 | C41: South | D41: FOOTWEAR | E41: AlpineGrip Sandal | F41: 1 | G41: 52.33 | H41: Online | I41: Lucas Martinez | J41: =IFERROR(DATEVALUE(B41),"") -> 45689 | K41: =IF(A41="","",PROPER(TRIM(C41))) -> South | L41: =IF(A41="","",PROPER(TRIM(D41))) -> Footwear | M41: =IFERROR(VALUE(F41),0) -> 1 | N41: =IFERROR(VALUE(SUBSTITUTE(G41,"$","")),0) -> 52.33 | O41: =IF(A41="",0,IF(COUNTIF($A$2:A41,A41)>1,1,0)) -> 0 | P41: =IF(AND(A41<>"",J41<>"",M41>0,N41>0,O41=0),1,0) -> 1 | Q41: =IF(P41=1,M41*N41,0) -> 52.33
A42: 10017 | B42: unknown | C42: East | D42: Apparel | E42: Merino Base Layer | F42: 3 | G42: $54.40 | H42: Wholesale | I42: Daniel Nguyen | J42: =IFERROR(DATEVALUE(B42),"") | K42: =IF(A42="","",PROPER(TRIM(C42))) -> East | L42: =IF(A42="","",PROPER(TRIM(D42))) -> Apparel | M42: =IFERROR(VALUE(F42),0) -> 3 | N42: =IFERROR(VALUE(SUBSTITUTE(G42,"$","")),0) -> 54.4 | O42: =IF(A42="",0,IF(COUNTIF($A$2:A42,A42)>1,1,0)) -> 0 | P42: =IF(AND(A42<>"",J42<>"",M42>0,N42>0,O42=0),1,0) -> 0 | Q42: =IF(P42=1,M42*N42,0) -> 0
A43: 10589 | B43: 2024-10-23 | C43: South | D43: Footwear | E43: Ridgeline Boot | F43: 1 | G43: 152.62 | H43: Online | I43: Daniel Rossi | J43: =IFERROR(DATEVALUE(B43),"") -> 45588 | K43: =IF(A43="","",PROPER(TRIM(C43))) -> South | L43: =IF(A43="","",PROPER(TRIM(D43))) -> Footwear | M43: =IFERROR(VALUE(F43),0) -> 1 | N43: =IFERROR(VALUE(SUBSTITUTE(G43,"$","")),0) -> 152.62 | O43: =IF(A43="",0,IF(COUNTIF($A$2:A43,A43)>1,1,0)) -> 0 | P43: =IF(AND(A43<>"",J43<>"",M43>0,N43>0,O43=0),1,0) -> 1 | Q43: =IF(P43=1,M43*N43,0) -> 152.62
A44: 10172 | B44: 2024-06-16 | C44: east | D44: accessories | E44: Headlamp | F44: 1 | G44: 33.02 | H44: Wholesale | I44: James Brown | J44: =IFERROR(DATEVALUE(B44),"") -> 45459 | K44: =IF(A44="","",PROPER(TRIM(C44))) -> East | L44: =IF(A44="","",PROPER(TRIM(D44))) -> Accessories | M44: =IFERROR(VALUE(F44),0) -> 1 | N44: =IFERROR(VALUE(SUBSTITUTE(G44,"$","")),0) -> 33.02 | O44: =IF(A44="",0,IF(COUNTIF($A$2:A44,A44)>1,1,0)) -> 0 | P44: =IF(AND(A44<>"",J44<>"",M44>0,N44>0,O44=0),1,0) -> 1 | Q44: =IF(P44=1,M44*N44,0) -> 33.02
A45: 10448 | B45: 1/29/2025 | C45: MIDWEST | D45: APPAREL | E45: Convertible Hiking Pants | F45: 3 | G45: 68.76 | H45: In-Store | I45: James Hall | J45: =IFERROR(DATEVALUE(B45),"") -> 45686 | K45: =IF(A45="","",PROPER(TRIM(C45))) -> Midwest | L45: =IF(A45="","",PROPER(TRIM(D45))) -> Apparel | M45: =IFERROR(VALUE(F45),0) -> 3 | N45: =IFERROR(VALUE(SUBSTITUTE(G45,"$","")),0) -> 68.76 | O45: =IF(A45="",0,IF(COUNTIF($A$2:A45,A45)>1,1,0)) -> 0 | P45: =IF(AND(A45<>"",J45<>"",M45>0,N45>0,O45=0),1,0) -> 1 | Q45: =IF(P45=1,M45*N45,0) -> 206.28
A46: 10148 | B46: 2024-05-23 | C46: East | D46: Climbing Gear | E46: Carabiner 5-Pack | F46: 2 | G46: 42.67 | H46: Wholesale | I46: Grace Young | J46: =IFERROR(DATEVALUE(B46),"") -> 45435 | K46: =IF(A46="","",PROPER(TRIM(C46))) -> East | L46: =IF(A46="","",PROPER(TRIM(D46))) -> Climbing Gear | M46: =IFERROR(VALUE(F46),0) -> 2 | N46: =IFERROR(VALUE(SUBSTITUTE(G46,"$","")),0) -> 42.67 | O46: =IF(A46="",0,IF(COUNTIF($A$2:A46,A46)>1,1,0)) -> 0 | P46: =IF(AND(A46<>"",J46<>"",M46>0,N46>0,O46=0),1,0) -> 1 | Q46: =IF(P46=1,M46*N46,0) -> 85.34
A47: 10456 | B47: 2024-05-31 | C47: West | D47: camping gear | E47: 2-Person Tent | F47: 1 | G47: 218.53 | H47: In-Store | I47: Mia Rodriguez | J47: =IFERROR(DATEVALUE(B47),"") -> 45443 | K47: =IF(A47="","",PROPER(TRIM(C47))) -> West | L47: =IF(A47="","",PROPER(TRIM(D47))) -> Camping Gear | M47: =IFERROR(VALUE(F47),0) -> 1 | N47: =IFERROR(VALUE(SUBSTITUTE(G47,"$","")),0) -> 218.53 | O47: =IF(A47="",0,IF(COUNTIF($A$2:A47,A47)>1,1,0)) -> 0 | P47: =IF(AND(A47<>"",J47<>"",M47>0,N47>0,O47=0),1,0) -> 1 | Q47: =IF(P47=1,M47*N47,0) -> 218.53
A48: 10075 | B48: 2025-05-06 | C48: EAST | D48: CLIMBING GEAR | E48: Dynamic Rope 60m | F48: 1 | G48: 154.16 | H48: Wholesale | I48: Mia Martinez | J48: =IFERROR(DATEVALUE(B48),"") -> 45783 | K48: =IF(A48="","",PROPER(TRIM(C48))) -> East | L48: =IF(A48="","",PROPER(TRIM(D48))) -> Climbing Gear | M48: =IFERROR(VALUE(F48),0) -> 1 | N48: =IFERROR(VALUE(SUBSTITUTE(G48,"$","")),0) -> 154.16 | O48: =IF(A48="",0,IF(COUNTIF($A$2:A48,A48)>1,1,0)) -> 0 | P48: =IF(AND(A48<>"",J48<>"",M48>0,N48>0,O48=0),1,0) -> 1 | Q48: =IF(P48=1,M48*N48,0) -> 154.16
... A162: 10739 | B162: 2024-11-22 | C162: midwest | D162: Apparel | E162: Convertible Hiking Pants | F162: 1 | G162: $68.91 | H162: Wholesale | I162: Emma Clark | J162: =IFERROR(DATEVALUE(B162),"") -> 45618 | K162: =IF(A162="","",PROPER(TRIM(C162))) -> Midwest | L162: =IF(A162="","",PROPER(TRIM(D162))) -> Apparel | M162: =IFERROR(VALUE(F162),0) -> 1 | N162: =IFERROR(VALUE(SUBSTITUTE(G162,"$","")),0) -> 68.91 | O162: =IF(A162="",0,IF(COUNTIF($A$2:A162,A162)>1,1,0)) -> 0 | P162: =IF(AND(A162<>"",J162<>"",M162>0,N162>0,O162=0),1,0) -> 1 | Q162: =IF(P162=1,M162*N162,0) -> 68.91
A163: 10496 | B163: 8/1/2024 | C163: east | D163: camping gear | E163: Down Sleeping Bag | F163: 1 | H163: Online | I163: Olivia Garcia | J163: =IFERROR(DATEVALUE(B163),"") -> 45505 | K163: =IF(A163="","",PROPER(TRIM(C163))) -> East | L163: =IF(A163="","",PROPER(TRIM(D163))) -> Camping Gear | M163: =IFERROR(VALUE(F163),0) -> 1 | N163: =IFERROR(VALUE(SUBSTITUTE(G163,"$","")),0) -> 0 | O163: =IF(A163="",0,IF(COUNTIF($A$2:A163,A163)>1,1,0)) -> 0 | P163: =IF(AND(A163<>"",J163<>"",M163>0,N163>0,O163=0),1,0) -> 0 | Q163: =IF(P163=1,M163*N163,0) -> 0
A164: 10306 | B164: 6/20/2025 | C164: MIDWEST | D164: Apparel | E164: Convertible Hiking Pants | F164: 3 | G164: $69.40 | H164: Wholesale | I164: James Wright | J164: =IFERROR(DATEVALUE(B164),"") -> 45828 | K164: =IF(A164="","",PROPER(TRIM(C164))) -> Midwest | L164: =IF(A164="","",PROPER(TRIM(D164))) -> Apparel | M164: =IFERROR(VALUE(F164),0) -> 3 | N164: =IFERROR(VALUE(SUBSTITUTE(G164,"$","")),0) -> 69.4 | O164: =IF(A164="",0,IF(COUNTIF($A$2:A164,A164)>1,1,0)) -> 0 | P164: =IF(AND(A164<>"",J164<>"",M164>0,N164>0,O164=0),1,0) -> 1 | Q164: =IF(P164=1,M164*N164,0) -> 208.2
A165: 10404 | B165: 8/16/2024 | C165: West | D165: APPAREL | E165: Convertible Hiking Pants | F165: 1 | G165: 64.99 | H165: Online | I165: Liam Walker | J165: =IFERROR(DATEVALUE(B165),"") -> 45520 | K165: =IF(A165="","",PROPER(TRIM(C165))) -> West | L165: =IF(A165="","",PROPER(TRIM(D165))) -> Apparel | M165: =IFERROR(VALUE(F165),0) -> 1 | N165: =IFERROR(VALUE(SUBSTITUTE(G165,"$","")),0) -> 64.99 | O165: =IF(A165="",0,IF(COUNTIF($A$2:A165,A165)>1,1,0)) -> 0 | P165: =IF(AND(A165<>"",J165<>"",M165>0,N165>0,O165=0),1,0) -> 1 | Q165: =IF(P165=1,M165*N165,0) -> 64.99
A166: 10666 | B166: 16-Sep-2024 | C166: Midwest | D166: Accessories | E166: Trekking Poles | F166: 3 | G166: 55.74 | H166: Online | I166: Maria Rossi | J166: =IFERROR(DATEVALUE(B166),"") -> 45551 | K166: =IF(A166="","",PROPER(TRIM(C166))) -> Midwest | L166: =IF(A166="","",PROPER(TRIM(D166))) -> Accessories | M166: =IFERROR(VALUE(F166),0) -> 3 | N166: =IFERROR(VALUE(SUBSTITUTE(G166,"$","")),0) -> 55.74 | O166: =IF(A166="",0,IF(COUNTIF($A$2:A166,A166)>1,1,0)) -> 0 | P166: =IF(AND(A166<>"",J166<>"",M166>0,N166>0,O166=0),1,0) -> 1 | Q166: =IF(P166=1,M166*N166,0) -> 167.22
A167: 10334 | B167: 2025-03-24 | C167: west | D167: apparel | E167: Merino Base Layer | F167: 1 | H167: In-Store | I167: Grace Wright | J167: =IFERROR(DATEVALUE(B167),"") -> 45740 | K167: =IF(A167="","",PROPER(TRIM(C167))) -> West | L167: =IF(A167="","",PROPER(TRIM(D167))) -> Apparel | M167: =IFERROR(VALUE(F167),0) -> 1 | N167: =IFERROR(VALUE(SUBSTITUTE(G167,"$","")),0) -> 0 | O167: =IF(A167="",0,IF(COUNTIF($A$2:A167,A167)>1,1,0)) -> 0 | P167: =IF(AND(A167<>"",J167<>"",M167>0,N167>0,O167=0),1,0) -> 0 | Q167: =IF(P167=1,M167*N167,0) -> 0
A168: 10577 | B168: 2025-06-03 | C168: West | D168: climbing gear | E168: Climbing Harness | F168: 1 | G168: $98.62 | H168: Wholesale | I168: Noah Rodriguez | J168: =IFERROR(DATEVALUE(B168),"") -> 45811 | K168: =IF(A168="","",PROPER(TRIM(C168))) -> West | L168: =IF(A168="","",PROPER(TRIM(D168))) -> Climbing Gear | M168: =IFERROR(VALUE(F168),0) -> 1 | N168: =IFERROR(VALUE(SUBSTITUTE(G168,"$","")),0) -> 98.62 | O168: =IF(A168="",0,IF(COUNTIF($A$2:A168,A168)>1,1,0)) -> 0 | P168: =IF(AND(A168<>"",J168<>"",M168>0,N168>0,O168=0),1,0) -> 1 | Q168: =IF(P168=1,M168*N168,0) -> 98.62
A169: 10111 | B169: 20-Feb-2024 | C169: south | D169: CLIMBING GEAR | E169: Chalk Bag | F169: 1 | G169: 20.72 | H169: In-Store | I169: James Davis | J169: =IFERROR(DATEVALUE(B169),"") -> 45342 | K169: =IF(A169="","",PROPER(TRIM(C169))) -> South | L169: =IF(A169="","",PROPER(TRIM(D169))) -> Climbing Gear | M169: =IFERROR(VALUE(F169),0) -> 1 | N169: =IFERROR(VALUE(SUBSTITUTE(G169,"$","")),0) -> 20.72 | O169: =IF(A169="",0,IF(COUNTIF($A$2:A169,A169)>1,1,0)) -> 0 | P169: =IF(AND(A169<>"",J169<>"",M169>0,N169>0,O169=0),1,0) -> 1 | Q169: =IF(P169=1,M169*N169,0) -> 20.72
A170: 10302 | B170: 2024-09-21 | C170: South | D170: footwear | E170: Summit Trail Runner | F170: 2 | G170: 94.66 | H170: In-Store | I170: Ava Rossi | J170: =IFERROR(DATEVALUE(B170),"") -> 45556 | K170: =IF(A170="","",PROPER(TRIM(C170))) -> South | L170: =IF(A170="","",PROPER(TRIM(D170))) -> Footwear | M170: =IFERROR(VALUE(F170),0) -> 2 | N170: =IFERROR(VALUE(SUBSTITUTE(G170,"$","")),0) -> 94.66 | O170: =IF(A170="",0,IF(COUNTIF($A$2:A170,A170)>1,1,0)) -> 0 | P170: =IF(AND(A170<>"",J170<>"",M170>0,N170>0,O170=0),1,0) -> 1 | Q170: =IF(P170=1,M170*N170,0) -> 189.32
A171: 10123 | B171: 2025-05-20 | C171: Midwest | D171: Accessories | E171: Hydration Pack | F171: 1 | G171: $81.72 | H171: Online | I171: Zoe Khan | J171: =IFERROR(DATEVALUE(B171),"") -> 45797 | K171: =IF(A171="","",PROPER(TRIM(C171))) -> Midwest | L171: =IF(A171="","",PROPER(TRIM(D171))) -> Accessories | M171: =IFERROR(VALUE(F171),0) -> 1 | N171: =IFERROR(VALUE(SUBSTITUTE(G171,"$","")),0) -> 81.72 | O171: =IF(A171="",0,IF(COUNTIF($A$2:A171,A171)>1,1,0)) -> 0 | P171: =IF(AND(A171<>"",J171<>"",M171>0,N171>0,O171=0),1,0) -> 1 | Q171: =IF(P171=1,M171*N171,0) -> 81.72
A172: 10301 | B172: 4/12/2025 | C172: midwest | D172: CLIMBING GEAR | E172: Dynamic Rope 60m | F172: 5 | G172: $156.39 | H172: Online | I172: Olivia Smith | J172: =IFERROR(DATEVALUE(B172),"") -> 45759 | K172: =IF(A172="","",PROPER(TRIM(C172))) -> Midwest | L172: =IF(A172="","",PROPER(TRIM(D172))) -> Climbing Gear | M172: =IFERROR(VALUE(F172),0) -> 5 | N172: =IFERROR(VALUE(SUBSTITUTE(G172,"$","")),0) -> 156.39 | O172: =IF(A172="",0,IF(COUNTIF($A$2:A172,A172)>1,1,0)) -> 0 | P172: =IF(AND(A172<>"",J172<>"",M172>0,N172>0,O172=0),1,0) -> 1 | Q172: =IF(P172=1,M172*N172,0) -> 781.95
A173: 10512 | B173: 2/6/2024 | C173: East | D173: footwear | E173: Ridgeline Boot | F173: 3 | G173: 140.30 | H173: Wholesale | I173: Zoe Thompson | J173: =IFERROR(DATEVALUE(B173),"") -> 45328 | K173: =IF(A173="","",PROPER(TRIM(C173))) -> East | L173: =IF(A173="","",PROPER(TRIM(D173))) -> Footwear | M173: =IFERROR(VALUE(F173),0) -> 3 | N173: =IFERROR(VALUE(SUBSTITUTE(G173,"$","")),0) -> 140.3 | O173: =IF(A173="",0,IF(COUNTIF($A$2:A173,A173)>1,1,0)) -> 0 | P173: =IF(AND(A173<>"",J173<>"",M173>0,N173>0,O173=0),1,0) -> 1 | Q173: =IF(P173=1,M173*N173,0) -> 420.9
A174: 10564 | B174: 8/7/2024 | C174: Midwest | D174: apparel | E174: Trail Fleece | F174: 2 | G174: 84.71 | H174: Wholesale | I174: Grace Hall | J174: =IFERROR(DATEVALUE(B174),"") -> 45511 | K174: =IF(A174="","",PROPER(TRIM(C174))) -> Midwest | L174: =IF(A174="","",PROPER(TRIM(D174))) -> Apparel | M174: =IFERROR(VALUE(F174),0) -> 2 | N174: =IFERROR(VALUE(SUBSTITUTE(G174,"$","")),0) -> 84.71 | O174: =IF(A174="",0,IF(COUNTIF($A$2:A174,A174)>1,1,0)) -> 0 | P174: =IF(AND(A174<>"",J174<>"",M174>0,N174>0,O174=0),1,0) -> 1 | Q174: =IF(P174=1,M174*N174,0) -> 169.42
...

Sheet Dashboard
B2: Anvik Trail Co. — Sales Performance Dashboard
B3: All figures below update live from the filters in row 5.
B5: Region | C5: All | D5: Category | E5: All | F5: Channel | G5: All | H5: Start Date | I5: 2024-01-01 | J5: End Date | K5: 2025-06-30
B7: Total Revenue | E7: Total Orders | H7: Units Sold | K7: Avg Order Value
B8: =SUMIFS('Raw Data'!$Q$2:$Q$824,'Raw Data'!$P$2:$P$824,1,'Raw Data'!$J$2:$J$824,">="&I5,'Raw Data'!$J$2:$J$824,"<="&K5,'Raw Data'!$K$2:$K$824,IF(C5="All","*",C5),'Raw Data'!$L$2:$L$824,IF(E5="All","*",E5),'Raw Data'!$H$2:$H$824,IF(G5="All","*",G5)) -> 142039.22 | E8: =COUNTIFS('Raw Data'!$P$2:$P$824,1,'Raw Data'!$J$2:$J$824,">="&I5,'Raw Data'!$J$2:$J$824,"<="&K5,'Raw Data'!$K$2:$K$824,IF(C5="All","*",C5),'Raw Data'!$L$2:$L$824,IF(E5="All","*",E5),'Raw Data'!$H$2:$H$824,IF(G5="All","*",G5)) -> 713 | H8: =SUMIFS('Raw Data'!$M$2:$M$824,'Raw Data'!$P$2:$P$824,1,'Raw Data'!$J$2:$J$824,">="&I5,'Raw Data'!$J$2:$J$824,"<="&K5,'Raw Data'!$K$2:$K$824,IF(C5="All","*",C5),'Raw Data'!$L$2:$L$824,IF(E5="All","*",E5),'Raw Data'!$H$2:$H$824,IF(G5="All","*",G5)) -> 1462 | K8: =IFERROR(B8/E8,0) -> 199.21349
B11: Revenue by Region | E11: Revenue by Category | H11: Revenue by Channel | K11: Revenue by Month
B12: Region | C12: Revenue | E12: Category | F12: Revenue | H12: Channel | I12: Revenue | K12: Month | L12: Revenue
B13: West | C13: =SUMIFS('Raw Data'!$Q$2:$Q$824,'Raw Data'!$P$2:$P$824,1,'Raw Data'!$J$2:$J$824,">="&I5,'Raw Data'!$J$2:$J$824,"<="&K5,'Raw Data'!$K$2:$K$824,B13,'Raw Data'!$L$2:$L$824,IF(E5="All","*",E5),'Raw Data'!$H$2:$H$824,IF(G5="All","*",G5)) -> 35596.94 | E13: Footwear | F13: =SUMIFS('Raw Data'!$Q$2:$Q$824,'Raw Data'!$P$2:$P$824,1,'Raw Data'!$J$2:$J$824,">="&I5,'Raw Data'!$J$2:$J$824,"<="&K5,'Raw Data'!$K$2:$K$824,IF(C5="All","*",C5),'Raw Data'!$L$2:$L$824,E13,'Raw Data'!$H$2:$H$824,IF(G5="All","*",G5)) -> 32759.83 | H13: Online | I13: =SUMIFS('Raw Data'!$Q$2:$Q$824,'Raw Data'!$P$2:$P$824,1,'Raw Data'!$J$2:$J$824,">="&I5,'Raw Data'!$J$2:$J$824,"<="&K5,'Raw Data'!$K$2:$K$824,IF(C5="All","*",C5),'Raw Data'!$L$2:$L$824,IF(E5="All","*",E5),'Raw Data'!$H$2:$H$824,H13) -> 49797.45 | K13: 2024-01-01 | L13: =SUMIFS('Raw Data'!$Q$2:$Q$824,'Raw Data'!$P$2:$P$824,1,'Raw Data'!$J$2:$J$824,">="&K13,'Raw Data'!$J$2:$J$824,"<="&(DATE(YEAR(K13),MONTH(K13)+1,1)-1),'Raw Data'!$J$2:$J$824,">="&I5,'Raw Data'!$J$2:$J$824,"<="&K5,'Raw Data'!$K$2:$K$824,IF(C5="All","*",C5),'Raw Data'!$L$2:$L$824,IF(E5="All","*",E5),'Raw Data'!$H$2:$H$824,IF(G5="All","*",G5)) -> 8316.55
B14: East | C14: =SUMIFS('Raw Data'!$Q$2:$Q$824,'Raw Data'!$P$2:$P$824,1,'Raw Data'!$J$2:$J$824,">="&I5,'Raw Data'!$J$2:$J$824,"<="&K5,'Raw Data'!$K$2:$K$824,B14,'Raw Data'!$L$2:$L$824,IF(E5="All","*",E5),'Raw Data'!$H$2:$H$824,IF(G5="All","*",G5)) -> 32611.07 | E14: Apparel | F14: =SUMIFS('Raw Data'!$Q$2:$Q$824,'Raw Data'!$P$2:$P$824,1,'Raw Data'!$J$2:$J$824,">="&I5,'Raw Data'!$J$2:$J$824,"<="&K5,'Raw Data'!$K$2:$K$824,IF(C5="All","*",C5),'Raw Data'!$L$2:$L$824,E14,'Raw Data'!$H$2:$H$824,IF(G5="All","*",G5)) -> 29069.74 | H14: In-Store | I14: =SUMIFS('Raw Data'!$Q$2:$Q$824,'Raw Data'!$P$2:$P$824,1,'Raw Data'!$J$2:$J$824,">="&I5,'Raw Data'!$J$2:$J$824,"<="&K5,'Raw Data'!$K$2:$K$824,IF(C5="All","*",C5),'Raw Data'!$L$2:$L$824,IF(E5="All","*",E5),'Raw Data'!$H$2:$H$824,H14) -> 47785.66 | K14: 2024-02-01 | L14: =SUMIFS('Raw Data'!$Q$2:$Q$824,'Raw Data'!$P$2:$P$824,1,'Raw Data'!$J$2:$J$824,">="&K14,'Raw Data'!$J$2:$J$824,"<="&(DATE(YEAR(K14),MONTH(K14)+1,1)-1),'Raw Data'!$J$2:$J$824,">="&I5,'Raw Data'!$J$2:$J$824,"<="&K5,'Raw Data'!$K$2:$K$824,IF(C5="All","*",C5),'Raw Data'!$L$2:$L$824,IF(E5="All","*",E5),'Raw Data'!$H$2:$H$824,IF(G5="All","*",G5)) -> 7572.93
B15: Midwest | C15: =SUMIFS('Raw Data'!$Q$2:$Q$824,'Raw Data'!$P$2:$P$824,1,'Raw Data'!$J$2:$J$824,">="&I5,'Raw Data'!$J$2:$J$824,"<="&K5,'Raw Data'!$K$2:$K$824,B15,'Raw Data'!$L$2:$L$824,IF(E5="All","*",E5),'Raw Data'!$H$2:$H$824,IF(G5="All","*",G5)) -> 36181.53 | E15: Camping Gear | F15: =SUMIFS('Raw Data'!$Q$2:$Q$824,'Raw Data'!$P$2:$P$824,1,'Raw Data'!$J$2:$J$824,">="&I5,'Raw Data'!$J$2:$J$824,"<="&K5,'Raw Data'!$K$2:$K$824,IF(C5="All","*",C5),'Raw Data'!$L$2:$L$824,E15,'Raw Data'!$H$2:$H$824,IF(G5="All","*",G5)) -> 39637.01 | H15: Wholesale | I15: =SUMIFS('Raw Data'!$Q$2:$Q$824,'Raw Data'!$P$2:$P$824,1,'Raw Data'!$J$2:$J$824,">="&I5,'Raw Data'!$J$2:$J$824,"<="&K5,'Raw Data'!$K$2:$K$824,IF(C5="All","*",C5),'Raw Data'!$L$2:$L$824,IF(E5="All","*",E5),'Raw Data'!$H$2:$H$824,H15) -> 44456.11 | K15: 2024-03-01 | L15: =SUMIFS('Raw Data'!$Q$2:$Q$824,'Raw Data'!$P$2:$P$824,1,'Raw Data'!$J$2:$J$824,">="&K15,'Raw Data'!$J$2:$J$824,"<="&(DATE(YEAR(K15),MONTH(K15)+1,1)-1),'Raw Data'!$J$2:$J$824,">="&I5,'Raw Data'!$J$2:$J$824,"<="&K5,'Raw Data'!$K$2:$K$824,IF(C5="All","*",C5),'Raw Data'!$L$2:$L$824,IF(E5="All","*",E5),'Raw Data'!$H$2:$H$824,IF(G5="All","*",G5)) -> 9528.23
B16: South | C16: =SUMIFS('Raw Data'!$Q$2:$Q$824,'Raw Data'!$P$2:$P$824,1,'Raw Data'!$J$2:$J$824,">="&I5,'Raw Data'!$J$2:$J$824,"<="&K5,'Raw Data'!$K$2:$K$824,B16,'Raw Data'!$L$2:$L$824,IF(E5="All","*",E5),'Raw Data'!$H$2:$H$824,IF(G5="All","*",G5)) -> 37649.68 | E16: Climbing Gear | F16: =SUMIFS('Raw Data'!$Q$2:$Q$824,'Raw Data'!$P$2:$P$824,1,'Raw Data'!$J$2:$J$824,">="&I5,'Raw Data'!$J$2:$J$824,"<="&K5,'Raw Data'!$K$2:$K$824,IF(C5="All","*",C5),'Raw Data'!$L$2:$L$824,E16,'Raw Data'!$H$2:$H$824,IF(G5="All","*",G5)) -> 27925.06 | K16: 2024-04-01 | L16: =SUMIFS('Raw Data'!$Q$2:$Q$824,'Raw Data'!$P$2:$P$824,1,'Raw Data'!$J$2:$J$824,">="&K16,'Raw Data'!$J$2:$J$824,"<="&(DATE(YEAR(K16),MONTH(K16)+1,1)-1),'Raw Data'!$J$2:$J$824,">="&I5,'Raw Data'!$J$2:$J$824,"<="&K5,'Raw Data'!$K$2:$K$824,IF(C5="All","*",C5),'Raw Data'!$L$2:$L$824,IF(E5="All","*",E5),'Raw Data'!$H$2:$H$824,IF(G5="All","*",G5)) -> 8812.67
E17: Accessories | F17: =SUMIFS('Raw Data'!$Q$2:$Q$824,'Raw Data'!$P$2:$P$824,1,'Raw Data'!$J$2:$J$824,">="&I5,'Raw Data'!$J$2:$J$824,"<="&K5,'Raw Data'!$K$2:$K$824,IF(C5="All","*",C5),'Raw Data'!$L$2:$L$824,E17,'Raw Data'!$H$2:$H$824,IF(G5="All","*",G5)) -> 12647.58 | K17: 2024-05-01 | L17: =SUMIFS('Raw Data'!$Q$2:$Q$824,'Raw Data'!$P$2:$P$824,1,'Raw Data'!$J$2:$J$824,">="&K17,'Raw Data'!$J$2:$J$824,"<="&(DATE(YEAR(K17),MONTH(K17)+1,1)-1),'Raw Data'!$J$2:$J$824,">="&I5,'Raw Data'!$J$2:$J$824,"<="&K5,'Raw Data'!$K$2:$K$824,IF(C5="All","*",C5),'Raw Data'!$L$2:$L$824,IF(E5="All","*",E5),'Raw Data'!$H$2:$H$824,IF(G5="All","*",G5)) -> 9403.72
K18: 2024-06-01 | L18: =SUMIFS('Raw Data'!$Q$2:$Q$824,'Raw Data'!$P$2:$P$824,1,'Raw Data'!$J$2:$J$824,">="&K18,'Raw Data'!$J$2:$J$824,"<="&(DATE(YEAR(K18),MONTH(K18)+1,1)-1),'Raw Data'!$J$2:$J$824,">="&I5,'Raw Data'!$J$2:$J$824,"<="&K5,'Raw Data'!$K$2:$K$824,IF(C5="All","*",C5),'Raw Data'!$L$2:$L$824,IF(E5="All","*",E5),'Raw Data'!$H$2:$H$824,IF(G5="All","*",G5)) -> 10121.41
K19: 2024-07-01 | L19: =SUMIFS('Raw Data'!$Q$2:$Q$824,'Raw Data'!$P$2:$P$824,1,'Raw Data'!$J$2:$J$824,">="&K19,'Raw Data'!$J$2:$J$824,"<="&(DATE(YEAR(K19),MONTH(K19)+1,1)-1),'Raw Data'!$J$2:$J$824,">="&I5,'Raw Data'!$J$2:$J$824,"<="&K5,'Raw Data'!$K$2:$K$824,IF(C5="All","*",C5),'Raw Data'!$L$2:$L$824,IF(E5="All","*",E5),'Raw Data'!$H$2:$H$824,IF(G5="All","*",G5)) -> 10863.94
K20: 2024-08-01 | L20: =SUMIFS('Raw Data'!$Q$2:$Q$824,'Raw Data'!$P$2:$P$824,1,'Raw Data'!$J$2:$J$824,">="&K20,'Raw Data'!$J$2:$J$824,"<="&(DATE(YEAR(K20),MONTH(K20)+1,1)-1),'Raw Data'!$J$2:$J$824,">="&I5,'Raw Data'!$J$2:$J$824,"<="&K5,'Raw Data'!$K$2:$K$824,IF(C5="All","*",C5),'Raw Data'!$L$2:$L$824,IF(E5="All","*",E5),'Raw Data'!$H$2:$H$824,IF(G5="All","*",G5)) -> 7413.37
K21: 2024-09-01 | L21: =SUMIFS('Raw Data'!$Q$2:$Q$824,'Raw Data'!$P$2:$P$824,1,'Raw Data'!$J$2:$J$824,">="&K21,'Raw Data'!$J$2:$J$824,"<="&(DATE(YEAR(K21),MONTH(K21)+1,1)-1),'Raw Data'!$J$2:$J$824,">="&I5,'Raw Data'!$J$2:$J$824,"<="&K5,'Raw Data'!$K$2:$K$824,IF(C5="All","*",C5),'Raw Data'!$L$2:$L$824,IF(E5="All","*",E5),'Raw Data'!$H$2:$H$824,IF(G5="All","*",G5)) -> 6368.09
K22: 2024-10-01 | L22: =SUMIFS('Raw Data'!$Q$2:$Q$824,'Raw Data'!$P$2:$P$824,1,'Raw Data'!$J$2:$J$824,">="&K22,'Raw Data'!$J$2:$J$824,"<="&(DATE(YEAR(K22),MONTH(K22)+1,1)-1),'Raw Data'!$J$2:$J$824,">="&I5,'Raw Data'!$J$2:$J$824,"<="&K5,'Raw Data'!$K$2:$K$824,IF(C5="All","*",C5),'Raw Data'!$L$2:$L$824,IF(E5="All","*",E5),'Raw Data'!$H$2:$H$824,IF(G5="All","*",G5)) -> 7415.74
K23: 2024-11-01 | L23: =SUMIFS('Raw Data'!$Q$2:$Q$824,'Raw Data'!$P$2:$P$824,1,'Raw Data'!$J$2:$J$824,">="&K23,'Raw Data'!$J$2:$J$824,"<="&(DATE(YEAR(K23),MONTH(K23)+1,1)-1),'Raw Data'!$J$2:$J$824,">="&I5,'Raw Data'!$J$2:$J$824,"<="&K5,'Raw Data'!$K$2:$K$824,IF(C5="All","*",C5),'Raw Data'!$L$2:$L$824,IF(E5="All","*",E5),'Raw Data'!$H$2:$H$824,IF(G5="All","*",G5)) -> 7524.82
K24: 2024-12-01 | L24: =SUMIFS('Raw Data'!$Q$2:$Q$824,'Raw Data'!$P$2:$P$824,1,'Raw Data'!$J$2:$J$824,">="&K24,'Raw Data'!$J$2:$J$824,"<="&(DATE(YEAR(K24),MONTH(K24)+1,1)-1),'Raw Data'!$J$2:$J$824,">="&I5,'Raw Data'!$J$2:$J$824,"<="&K5,'Raw Data'!$K$2:$K$824,IF(C5="All","*",C5),'Raw Data'!$L$2:$L$824,IF(E5="All","*",E5),'Raw Data'!$H$2:$H$824,IF(G5="All","*",G5)) -> 6339.03
K25: 2025-01-01 | L25: =SUMIFS('Raw Data'!$Q$2:$Q$824,'Raw Data'!$P$2:$P$824,1,'Raw Data'!$J$2:$J$824,">="&K25,'Raw Data'!$J$2:$J$824,"<="&(DATE(YEAR(K25),MONTH(K25)+1,1)-1),'Raw Data'!$J$2:$J$824,">="&I5,'Raw Data'!$J$2:$J$824,"<="&K5,'Raw Data'!$K$2:$K$824,IF(C5="All","*",C5),'Raw Data'!$L$2:$L$824,IF(E5="All","*",E5),'Raw Data'!$H$2:$H$824,IF(G5="All","*",G5)) -> 7530.51
K26: 2025-02-01 | L26: =SUMIFS('Raw Data'!$Q$2:$Q$824,'Raw Data'!$P$2:$P$824,1,'Raw Data'!$J$2:$J$824,">="&K26,'Raw Data'!$J$2:$J$824,"<="&(DATE(YEAR(K26),MONTH(K26)+1,1)-1),'Raw Data'!$J$2:$J$824,">="&I5,'Raw Data'!$J$2:$J$824,"<="&K5,'Raw Data'!$K$2:$K$824,IF(C5="All","*",C5),'Raw Data'!$L$2:$L$824,IF(E5="All","*",E5),'Raw Data'!$H$2:$H$824,IF(G5="All","*",G5)) -> 5615.96
K27: 2025-03-01 | L27: =SUMIFS('Raw Data'!$Q$2:$Q$824,'Raw Data'!$P$2:$P$824,1,'Raw Data'!$J$2:$J$824,">="&K27,'Raw Data'!$J$2:$J$824,"<="&(DATE(YEAR(K27),MONTH(K27)+1,1)-1),'Raw Data'!$J$2:$J$824,">="&I5,'Raw Data'!$J$2:$J$824,"<="&K5,'Raw Data'!$K$2:$K$824,IF(C5="All","*",C5),'Raw Data'!$L$2:$L$824,IF(E5="All","*",E5),'Raw Data'!$H$2:$H$824,IF(G5="All","*",G5)) -> 5660.67
K28: 2025-04-01 | L28: =SUMIFS('Raw Data'!$Q$2:$Q$824,'Raw Data'!$P$2:$P$824,1,'Raw Data'!$J$2:$J$824,">="&K28,'Raw Data'!$J$2:$J$824,"<="&(DATE(YEAR(K28),MONTH(K28)+1,1)-1),'Raw Data'!$J$2:$J$824,">="&I5,'Raw Data'!$J$2:$J$824,"<="&K5,'Raw Data'!$K$2:$K$824,IF(C5="All","*",C5),'Raw Data'!$L$2:$L$824,IF(E5="All","*",E5),'Raw Data'!$H$2:$H$824,IF(G5="All","*",G5)) -> 8669.39
K29: 2025-05-01 | L29: =SUMIFS('Raw Data'!$Q$2:$Q$824,'Raw Data'!$P$2:$P$824,1,'Raw Data'!$J$2:$J$824,">="&K29,'Raw Data'!$J$2:$J$824,"<="&(DATE(YEAR(K29),MONTH(K29)+1,1)-1),'Raw Data'!$J$2:$J$824,">="&I5,'Raw Data'!$J$2:$J$824,"<="&K5,'Raw Data'!$K$2:$K$824,IF(C5="All","*",C5),'Raw Data'!$L$2:$L$824,IF(E5="All","*",E5),'Raw Data'!$H$2:$H$824,IF(G5="All","*",G5)) -> 7287.48
K30: 2025-06-01 | L30: =SUMIFS('Raw Data'!$Q$2:$Q$824,'Raw Data'!$P$2:$P$824,1,'Raw Data'!$J$2:$J$824,">="&K30,'Raw Data'!$J$2:$J$824,"<="&(DATE(YEAR(K30),MONTH(K30)+1,1)-1),'Raw Data'!$J$2:$J$824,">="&I5,'Raw Data'!$J$2:$J$824,"<="&K5,'Raw Data'!$K$2:$K$824,IF(C5="All","*",C5),'Raw Data'!$L$2:$L$824,IF(E5="All","*",E5),'Raw Data'!$H$2:$H$824,IF(G5="All","*",G5)) -> 7594.71

Sheet Data Cleaning Log
B2: Data Cleaning Log
B3: Every count below is a live formula against Raw Data — re-run the export and this log re-tallies itself.
B5: Issue | C5: Row Count | D5: How it was handled
B6: Total rows in raw export (incl. blanks) | C6: =COUNTA('Raw Data'!$A$2:$A$824)+COUNTBLANK('Raw Data'!$A$2:$A$824) -> 823 | D6: Baseline row count for the export.
B7: Fully blank rows | C7: =COUNTBLANK('Raw Data'!$A$2:$A$824) -> 8 | D7: Ignored automatically — cleaning formulas short-circuit to blank/0 on empty OrderID.
B8: Duplicate order rows (double entry) | C8: =SUM('Raw Data'!$O$2:$O$824) -> 35 | D8: Flagged via COUNTIF on OrderID; first occurrence kept, repeats excluded from all totals.
B9: Unparseable / garbage dates | C9: =SUMPRODUCT(('Raw Data'!$A$2:$A$824<>"")*('Raw Data'!$J$2:$J$824="")) -> 32 | D9: DATEVALUE() wrapped in IFERROR; unparseable text ("N/A", "TBD", etc.) becomes blank and the row is excluded.
B10: Invalid quantity (zero / negative) | C10: =SUMPRODUCT(('Raw Data'!$A$2:$A$824<>"")*('Raw Data'!$M$2:$M$824<=0)) -> 20 | D10: Rows with quantity ≤ 0 are excluded from revenue and unit totals.
B11: Missing / blank unit price | C11: =SUMPRODUCT(('Raw Data'!$A$2:$A$824<>"")*('Raw Data'!$N$2:$N$824<=0)) -> 16 | D11: SUBSTITUTE strips "$", VALUE() wrapped in IFERROR; blank/unparseable price rows excluded.
B12: Region/Category text inconsistently cased or padded | C12: =SUMPRODUCT(('Raw Data'!$C$2:$C$824<>PROPER(TRIM('Raw Data'!$C$2:$C$824)))*('Raw Data'!$A$2:$A$824<>"")) -> 240 | D12: TRIM() + PROPER() standardize casing/whitespace before any grouping or filtering.
B13: Clean, valid rows used in the dashboard | C13: =SUM('Raw Data'!$P$2:$P$824) -> 713 | D13: Rows passing every check above (unique, valid date, valid qty, valid price).
